2024-12-01 15:09:38,247 - app.services.s3 - INFO - s3.py:22 - Initialized S3 service with bucket: bigdata-f24-t1-assignment
2024-12-01 15:12:25,909 - app.services.s3 - INFO - s3.py:22 - Initialized S3 service with bucket: bigdata-f24-t1-assignment
2024-12-01 15:13:51,813 - app.services.s3 - INFO - s3.py:22 - Initialized S3 service with bucket: bigdata-f24-t1-assignment
2024-12-01 15:13:55,789 - app.api.v1.files - INFO - files.py:29 - File upload initiated by user 340003bc-3dbc-4c0b-8c4c-777126934e5d: chat_export (11).pdf
2024-12-01 15:13:55,789 - app.services.s3 - INFO - s3.py:36 - Starting file upload. User: 340003bc-3dbc-4c0b-8c4c-777126934e5d, File: chat_export (11).pdf
2024-12-01 15:13:55,790 - app.services.s3 - DEBUG - s3.py:43 - Generated S3 key: users/340003bc-3dbc-4c0b-8c4c-777126934e5d/85d6d558-e86a-47e4-a37a-ffd5d3244ff5.pdf
2024-12-01 15:13:55,790 - app.services.s3 - DEBUG - s3.py:44 - File details - Size: 236395, Type: application/pdf
2024-12-01 15:13:56,636 - app.services.s3 - ERROR - logger.py:56 - {
  "error_type": "TypeError",
  "error_message": "object NoneType can't be used in 'await' expression",
  "traceback": "Traceback (most recent call last):\n  File \"/Users/saisuryamadhav/Documents/University/LearnLab/backend/app/services/s3.py\", line 47, in upload_file\n    await self.s3_client.upload_fileobj(\nTypeError: object NoneType can't be used in 'await' expression\n",
  "user_id": "340003bc-3dbc-4c0b-8c4c-777126934e5d",
  "filename": "chat_export (11).pdf",
  "operation": "upload"
}
2024-12-01 15:13:56,639 - app.api.v1.files - ERROR - logger.py:56 - {
  "error_type": "HTTPException",
  "error_message": "500: Failed to upload file to S3",
  "traceback": "Traceback (most recent call last):\n  File \"/Users/saisuryamadhav/Documents/University/LearnLab/backend/app/services/s3.py\", line 47, in upload_file\n    await self.s3_client.upload_fileobj(\nTypeError: object NoneType can't be used in 'await' expression\n\nDuring handling of the above exception, another exception occurred:\n\nTraceback (most recent call last):\n  File \"/Users/saisuryamadhav/Documents/University/LearnLab/backend/app/api/v1/files.py\", line 33, in upload_file\n    s3_key = await s3_service.upload_file(file, current_user.id)\n             ^^^^^^^^^^^^^^^^^^^^^^^^^^^^^^^^^^^^^^^^^^^^^^^^^^^\n  File \"/Users/saisuryamadhav/Documents/University/LearnLab/backend/app/services/s3.py\", line 77, in upload_file\n    raise HTTPException(\nfastapi.exceptions.HTTPException: 500: Failed to upload file to S3\n",
  "user_id": "340003bc-3dbc-4c0b-8c4c-777126934e5d",
  "filename": "chat_export (11).pdf"
}
2024-12-01 15:16:09,629 - app.services.s3 - INFO - s3.py:22 - Initialized S3 service with bucket: bigdata-f24-t1-assignment
2024-12-01 15:16:15,263 - app.api.v1.files - INFO - files.py:29 - File upload initiated by user 340003bc-3dbc-4c0b-8c4c-777126934e5d: chat_export (11).pdf
2024-12-01 15:16:15,263 - app.services.s3 - INFO - s3.py:36 - Starting file upload. User: 340003bc-3dbc-4c0b-8c4c-777126934e5d, File: chat_export (11).pdf
2024-12-01 15:16:15,264 - app.services.s3 - DEBUG - s3.py:43 - Generated S3 key: users/340003bc-3dbc-4c0b-8c4c-777126934e5d/25a48056-9810-43e6-8275-dcde8328cf8f.pdf
2024-12-01 15:16:15,264 - app.services.s3 - DEBUG - s3.py:44 - File details - Size: 236395, Type: application/pdf
2024-12-01 15:16:15,796 - app.services.s3 - INFO - s3.py:57 - File upload successful. Time taken: 0.53s
2024-12-01 15:16:15,797 - app.api.v1.files - DEBUG - files.py:34 - File uploaded to S3. Key: users/340003bc-3dbc-4c0b-8c4c-777126934e5d/25a48056-9810-43e6-8275-dcde8328cf8f.pdf
2024-12-01 15:16:15,821 - app.api.v1.files - DEBUG - files.py:48 - Database record created for file: 70160a20-bec3-4128-a7f0-132efbf294fa
2024-12-01 15:16:15,821 - app.services.s3 - DEBUG - s3.py:87 - Generating presigned URL for key: users/340003bc-3dbc-4c0b-8c4c-777126934e5d/25a48056-9810-43e6-8275-dcde8328cf8f.pdf
2024-12-01 15:16:15,822 - app.services.s3 - DEBUG - s3.py:98 - Generated presigned URL with expiry: 3600s
2024-12-01 15:16:15,822 - app.api.v1.files - INFO - files.py:65 - File upload completed successfully. Time taken: 0.56s
2024-12-01 15:21:37,011 - app.services.s3 - INFO - s3.py:22 - Initialized S3 service with bucket: bigdata-f24-t1-assignment
2024-12-01 15:22:13,622 - app.api.v1.files - INFO - files.py:29 - File upload initiated by user 340003bc-3dbc-4c0b-8c4c-777126934e5d: chat_export (11).pdf
2024-12-01 15:22:13,623 - app.services.s3 - INFO - s3.py:36 - Starting file upload. User: 340003bc-3dbc-4c0b-8c4c-777126934e5d, File: chat_export (11).pdf
2024-12-01 15:22:13,623 - app.services.s3 - DEBUG - s3.py:43 - Generated S3 key: users/340003bc-3dbc-4c0b-8c4c-777126934e5d/109076fb-0435-4c73-a6c4-33f975ef015e.pdf
2024-12-01 15:22:13,623 - app.services.s3 - DEBUG - s3.py:44 - File details - Size: 236395, Type: application/pdf
2024-12-01 15:22:14,444 - app.services.s3 - INFO - s3.py:57 - File upload successful. Time taken: 0.82s
2024-12-01 15:22:14,444 - app.api.v1.files - DEBUG - files.py:34 - File uploaded to S3. Key: users/340003bc-3dbc-4c0b-8c4c-777126934e5d/109076fb-0435-4c73-a6c4-33f975ef015e.pdf
2024-12-01 15:22:14,458 - app.api.v1.files - DEBUG - files.py:48 - Database record created for file: 32db86f1-3420-4f0d-aaa0-966673819605
2024-12-01 15:22:14,458 - app.services.s3 - DEBUG - s3.py:87 - Generating presigned URL for key: users/340003bc-3dbc-4c0b-8c4c-777126934e5d/109076fb-0435-4c73-a6c4-33f975ef015e.pdf
2024-12-01 15:22:14,460 - app.services.s3 - DEBUG - s3.py:98 - Generated presigned URL with expiry: 3600s
2024-12-01 15:22:14,460 - app.api.v1.files - INFO - files.py:65 - File upload completed successfully. Time taken: 0.84s
2024-12-01 20:23:01,945 - app.services.s3 - INFO - s3.py:22 - Initialized S3 service with bucket: learnlab-files
2024-12-01 20:25:59,144 - app.services.s3 - INFO - s3.py:22 - Initialized S3 service with bucket: learnlab-files
2024-12-01 20:27:38,322 - app.api.v1.files - INFO - files.py:29 - File upload initiated by user 340003bc-3dbc-4c0b-8c4c-777126934e5d: chat_export (11).pdf
2024-12-01 20:27:38,324 - app.services.s3 - INFO - s3.py:36 - Starting file upload. User: 340003bc-3dbc-4c0b-8c4c-777126934e5d, File: chat_export (11).pdf
2024-12-01 20:27:38,325 - app.services.s3 - DEBUG - s3.py:43 - Generated S3 key: users/340003bc-3dbc-4c0b-8c4c-777126934e5d/9883b5cf-e96a-430e-b86e-5b4082bb7b0b.pdf
2024-12-01 20:27:38,325 - app.services.s3 - DEBUG - s3.py:44 - File details - Size: 236395, Type: application/pdf
2024-12-01 20:27:38,619 - app.services.s3 - ERROR - logger.py:56 - {
  "error_type": "ClientError",
  "error_message": "An error occurred (AccessDenied) when calling the PutObject operation: Access Denied",
  "traceback": "Traceback (most recent call last):\n  File \"/app/app/services/s3.py\", line 47, in upload_file\n    self.s3_client.upload_fileobj(\n  File \"/usr/local/lib/python3.12/site-packages/boto3/s3/inject.py\", line 642, in upload_fileobj\n    return future.result()\n           ^^^^^^^^^^^^^^^\n  File \"/usr/local/lib/python3.12/site-packages/s3transfer/futures.py\", line 103, in result\n    return self._coordinator.result()\n           ^^^^^^^^^^^^^^^^^^^^^^^^^^\n  File \"/usr/local/lib/python3.12/site-packages/s3transfer/futures.py\", line 264, in result\n    raise self._exception\n  File \"/usr/local/lib/python3.12/site-packages/s3transfer/tasks.py\", line 135, in __call__\n    return self._execute_main(kwargs)\n           ^^^^^^^^^^^^^^^^^^^^^^^^^^\n  File \"/usr/local/lib/python3.12/site-packages/s3transfer/tasks.py\", line 158, in _execute_main\n    return_value = self._main(**kwargs)\n                   ^^^^^^^^^^^^^^^^^^^^\n  File \"/usr/local/lib/python3.12/site-packages/s3transfer/upload.py\", line 762, in _main\n    client.put_object(Bucket=bucket, Key=key, Body=body, **extra_args)\n  File \"/usr/local/lib/python3.12/site-packages/botocore/client.py\", line 569, in _api_call\n    return self._make_api_call(operation_name, kwargs)\n           ^^^^^^^^^^^^^^^^^^^^^^^^^^^^^^^^^^^^^^^^^^^\n  File \"/usr/local/lib/python3.12/site-packages/botocore/client.py\", line 1023, in _make_api_call\n    raise error_class(parsed_response, operation_name)\nbotocore.exceptions.ClientError: An error occurred (AccessDenied) when calling the PutObject operation: Access Denied\n",
  "user_id": "340003bc-3dbc-4c0b-8c4c-777126934e5d",
  "filename": "chat_export (11).pdf",
  "operation": "upload",
  "error_code": "AccessDenied"
}
2024-12-01 20:27:38,620 - app.api.v1.files - ERROR - logger.py:56 - {
  "error_type": "HTTPException",
  "error_message": "500: AWS S3 error: Access Denied",
  "traceback": "Traceback (most recent call last):\n  File \"/app/app/services/s3.py\", line 47, in upload_file\n    self.s3_client.upload_fileobj(\n  File \"/usr/local/lib/python3.12/site-packages/boto3/s3/inject.py\", line 642, in upload_fileobj\n    return future.result()\n           ^^^^^^^^^^^^^^^\n  File \"/usr/local/lib/python3.12/site-packages/s3transfer/futures.py\", line 103, in result\n    return self._coordinator.result()\n           ^^^^^^^^^^^^^^^^^^^^^^^^^^\n  File \"/usr/local/lib/python3.12/site-packages/s3transfer/futures.py\", line 264, in result\n    raise self._exception\n  File \"/usr/local/lib/python3.12/site-packages/s3transfer/tasks.py\", line 135, in __call__\n    return self._execute_main(kwargs)\n           ^^^^^^^^^^^^^^^^^^^^^^^^^^\n  File \"/usr/local/lib/python3.12/site-packages/s3transfer/tasks.py\", line 158, in _execute_main\n    return_value = self._main(**kwargs)\n                   ^^^^^^^^^^^^^^^^^^^^\n  File \"/usr/local/lib/python3.12/site-packages/s3transfer/upload.py\", line 762, in _main\n    client.put_object(Bucket=bucket, Key=key, Body=body, **extra_args)\n  File \"/usr/local/lib/python3.12/site-packages/botocore/client.py\", line 569, in _api_call\n    return self._make_api_call(operation_name, kwargs)\n           ^^^^^^^^^^^^^^^^^^^^^^^^^^^^^^^^^^^^^^^^^^^\n  File \"/usr/local/lib/python3.12/site-packages/botocore/client.py\", line 1023, in _make_api_call\n    raise error_class(parsed_response, operation_name)\nbotocore.exceptions.ClientError: An error occurred (AccessDenied) when calling the PutObject operation: Access Denied\n\nDuring handling of the above exception, another exception occurred:\n\nTraceback (most recent call last):\n  File \"/app/app/api/v1/files.py\", line 33, in upload_file\n    s3_key = await s3_service.upload_file(file, current_user.id)\n             ^^^^^^^^^^^^^^^^^^^^^^^^^^^^^^^^^^^^^^^^^^^^^^^^^^^\n  File \"/app/app/services/s3.py\", line 67, in upload_file\n    raise HTTPException(\nfastapi.exceptions.HTTPException: 500: AWS S3 error: Access Denied\n",
  "user_id": "340003bc-3dbc-4c0b-8c4c-777126934e5d",
  "filename": "chat_export (11).pdf"
}
2024-12-01 20:36:10,605 - app.services.s3 - INFO - s3.py:22 - Initialized S3 service with bucket: learnlab-files
2024-12-01 20:36:19,871 - app.api.v1.files - INFO - files.py:29 - File upload initiated by user 340003bc-3dbc-4c0b-8c4c-777126934e5d: chat_export (11).pdf
2024-12-01 20:36:19,871 - app.services.s3 - INFO - s3.py:36 - Starting file upload. User: 340003bc-3dbc-4c0b-8c4c-777126934e5d, File: chat_export (11).pdf
2024-12-01 20:36:19,871 - app.services.s3 - DEBUG - s3.py:43 - Generated S3 key: users/340003bc-3dbc-4c0b-8c4c-777126934e5d/a3a8b079-875d-4b5c-bc8b-1e0aeaae189b.pdf
2024-12-01 20:36:19,872 - app.services.s3 - DEBUG - s3.py:44 - File details - Size: 236395, Type: application/pdf
2024-12-01 20:36:20,129 - app.services.s3 - ERROR - logger.py:56 - {
  "error_type": "ClientError",
  "error_message": "An error occurred (AccessDenied) when calling the PutObject operation: Access Denied",
  "traceback": "Traceback (most recent call last):\n  File \"/app/app/services/s3.py\", line 47, in upload_file\n    self.s3_client.upload_fileobj(\n  File \"/usr/local/lib/python3.12/site-packages/boto3/s3/inject.py\", line 642, in upload_fileobj\n    return future.result()\n           ^^^^^^^^^^^^^^^\n  File \"/usr/local/lib/python3.12/site-packages/s3transfer/futures.py\", line 103, in result\n    return self._coordinator.result()\n           ^^^^^^^^^^^^^^^^^^^^^^^^^^\n  File \"/usr/local/lib/python3.12/site-packages/s3transfer/futures.py\", line 264, in result\n    raise self._exception\n  File \"/usr/local/lib/python3.12/site-packages/s3transfer/tasks.py\", line 135, in __call__\n    return self._execute_main(kwargs)\n           ^^^^^^^^^^^^^^^^^^^^^^^^^^\n  File \"/usr/local/lib/python3.12/site-packages/s3transfer/tasks.py\", line 158, in _execute_main\n    return_value = self._main(**kwargs)\n                   ^^^^^^^^^^^^^^^^^^^^\n  File \"/usr/local/lib/python3.12/site-packages/s3transfer/upload.py\", line 762, in _main\n    client.put_object(Bucket=bucket, Key=key, Body=body, **extra_args)\n  File \"/usr/local/lib/python3.12/site-packages/botocore/client.py\", line 569, in _api_call\n    return self._make_api_call(operation_name, kwargs)\n           ^^^^^^^^^^^^^^^^^^^^^^^^^^^^^^^^^^^^^^^^^^^\n  File \"/usr/local/lib/python3.12/site-packages/botocore/client.py\", line 1023, in _make_api_call\n    raise error_class(parsed_response, operation_name)\nbotocore.exceptions.ClientError: An error occurred (AccessDenied) when calling the PutObject operation: Access Denied\n",
  "user_id": "340003bc-3dbc-4c0b-8c4c-777126934e5d",
  "filename": "chat_export (11).pdf",
  "operation": "upload",
  "error_code": "AccessDenied"
}
2024-12-01 20:36:20,131 - app.api.v1.files - ERROR - logger.py:56 - {
  "error_type": "HTTPException",
  "error_message": "500: AWS S3 error: Access Denied",
  "traceback": "Traceback (most recent call last):\n  File \"/app/app/services/s3.py\", line 47, in upload_file\n    self.s3_client.upload_fileobj(\n  File \"/usr/local/lib/python3.12/site-packages/boto3/s3/inject.py\", line 642, in upload_fileobj\n    return future.result()\n           ^^^^^^^^^^^^^^^\n  File \"/usr/local/lib/python3.12/site-packages/s3transfer/futures.py\", line 103, in result\n    return self._coordinator.result()\n           ^^^^^^^^^^^^^^^^^^^^^^^^^^\n  File \"/usr/local/lib/python3.12/site-packages/s3transfer/futures.py\", line 264, in result\n    raise self._exception\n  File \"/usr/local/lib/python3.12/site-packages/s3transfer/tasks.py\", line 135, in __call__\n    return self._execute_main(kwargs)\n           ^^^^^^^^^^^^^^^^^^^^^^^^^^\n  File \"/usr/local/lib/python3.12/site-packages/s3transfer/tasks.py\", line 158, in _execute_main\n    return_value = self._main(**kwargs)\n                   ^^^^^^^^^^^^^^^^^^^^\n  File \"/usr/local/lib/python3.12/site-packages/s3transfer/upload.py\", line 762, in _main\n    client.put_object(Bucket=bucket, Key=key, Body=body, **extra_args)\n  File \"/usr/local/lib/python3.12/site-packages/botocore/client.py\", line 569, in _api_call\n    return self._make_api_call(operation_name, kwargs)\n           ^^^^^^^^^^^^^^^^^^^^^^^^^^^^^^^^^^^^^^^^^^^\n  File \"/usr/local/lib/python3.12/site-packages/botocore/client.py\", line 1023, in _make_api_call\n    raise error_class(parsed_response, operation_name)\nbotocore.exceptions.ClientError: An error occurred (AccessDenied) when calling the PutObject operation: Access Denied\n\nDuring handling of the above exception, another exception occurred:\n\nTraceback (most recent call last):\n  File \"/app/app/api/v1/files.py\", line 33, in upload_file\n    s3_key = await s3_service.upload_file(file, current_user.id)\n             ^^^^^^^^^^^^^^^^^^^^^^^^^^^^^^^^^^^^^^^^^^^^^^^^^^^\n  File \"/app/app/services/s3.py\", line 67, in upload_file\n    raise HTTPException(\nfastapi.exceptions.HTTPException: 500: AWS S3 error: Access Denied\n",
  "user_id": "340003bc-3dbc-4c0b-8c4c-777126934e5d",
  "filename": "chat_export (11).pdf"
}
2024-12-01 20:54:30,489 - app.api.v1.files - INFO - files.py:29 - File upload initiated by user 340003bc-3dbc-4c0b-8c4c-777126934e5d: chat_export (11).pdf
2024-12-01 20:54:30,496 - app.services.s3 - INFO - s3.py:36 - Starting file upload. User: 340003bc-3dbc-4c0b-8c4c-777126934e5d, File: chat_export (11).pdf
2024-12-01 20:54:30,498 - app.services.s3 - DEBUG - s3.py:43 - Generated S3 key: users/340003bc-3dbc-4c0b-8c4c-777126934e5d/e289b566-ba7a-403c-a9e9-fb2e3159b6d6.pdf
2024-12-01 20:54:30,498 - app.services.s3 - DEBUG - s3.py:44 - File details - Size: 236395, Type: application/pdf
2024-12-01 20:54:30,895 - app.services.s3 - ERROR - logger.py:56 - {
  "error_type": "ClientError",
  "error_message": "An error occurred (AccessDenied) when calling the PutObject operation: Access Denied",
  "traceback": "Traceback (most recent call last):\n  File \"/app/app/services/s3.py\", line 47, in upload_file\n    self.s3_client.upload_fileobj(\n  File \"/usr/local/lib/python3.12/site-packages/boto3/s3/inject.py\", line 642, in upload_fileobj\n    return future.result()\n           ^^^^^^^^^^^^^^^\n  File \"/usr/local/lib/python3.12/site-packages/s3transfer/futures.py\", line 103, in result\n    return self._coordinator.result()\n           ^^^^^^^^^^^^^^^^^^^^^^^^^^\n  File \"/usr/local/lib/python3.12/site-packages/s3transfer/futures.py\", line 264, in result\n    raise self._exception\n  File \"/usr/local/lib/python3.12/site-packages/s3transfer/tasks.py\", line 135, in __call__\n    return self._execute_main(kwargs)\n           ^^^^^^^^^^^^^^^^^^^^^^^^^^\n  File \"/usr/local/lib/python3.12/site-packages/s3transfer/tasks.py\", line 158, in _execute_main\n    return_value = self._main(**kwargs)\n                   ^^^^^^^^^^^^^^^^^^^^\n  File \"/usr/local/lib/python3.12/site-packages/s3transfer/upload.py\", line 762, in _main\n    client.put_object(Bucket=bucket, Key=key, Body=body, **extra_args)\n  File \"/usr/local/lib/python3.12/site-packages/botocore/client.py\", line 569, in _api_call\n    return self._make_api_call(operation_name, kwargs)\n           ^^^^^^^^^^^^^^^^^^^^^^^^^^^^^^^^^^^^^^^^^^^\n  File \"/usr/local/lib/python3.12/site-packages/botocore/client.py\", line 1023, in _make_api_call\n    raise error_class(parsed_response, operation_name)\nbotocore.exceptions.ClientError: An error occurred (AccessDenied) when calling the PutObject operation: Access Denied\n",
  "user_id": "340003bc-3dbc-4c0b-8c4c-777126934e5d",
  "filename": "chat_export (11).pdf",
  "operation": "upload",
  "error_code": "AccessDenied"
}
2024-12-01 20:54:30,897 - app.api.v1.files - ERROR - logger.py:56 - {
  "error_type": "HTTPException",
  "error_message": "500: AWS S3 error: Access Denied",
  "traceback": "Traceback (most recent call last):\n  File \"/app/app/services/s3.py\", line 47, in upload_file\n    self.s3_client.upload_fileobj(\n  File \"/usr/local/lib/python3.12/site-packages/boto3/s3/inject.py\", line 642, in upload_fileobj\n    return future.result()\n           ^^^^^^^^^^^^^^^\n  File \"/usr/local/lib/python3.12/site-packages/s3transfer/futures.py\", line 103, in result\n    return self._coordinator.result()\n           ^^^^^^^^^^^^^^^^^^^^^^^^^^\n  File \"/usr/local/lib/python3.12/site-packages/s3transfer/futures.py\", line 264, in result\n    raise self._exception\n  File \"/usr/local/lib/python3.12/site-packages/s3transfer/tasks.py\", line 135, in __call__\n    return self._execute_main(kwargs)\n           ^^^^^^^^^^^^^^^^^^^^^^^^^^\n  File \"/usr/local/lib/python3.12/site-packages/s3transfer/tasks.py\", line 158, in _execute_main\n    return_value = self._main(**kwargs)\n                   ^^^^^^^^^^^^^^^^^^^^\n  File \"/usr/local/lib/python3.12/site-packages/s3transfer/upload.py\", line 762, in _main\n    client.put_object(Bucket=bucket, Key=key, Body=body, **extra_args)\n  File \"/usr/local/lib/python3.12/site-packages/botocore/client.py\", line 569, in _api_call\n    return self._make_api_call(operation_name, kwargs)\n           ^^^^^^^^^^^^^^^^^^^^^^^^^^^^^^^^^^^^^^^^^^^\n  File \"/usr/local/lib/python3.12/site-packages/botocore/client.py\", line 1023, in _make_api_call\n    raise error_class(parsed_response, operation_name)\nbotocore.exceptions.ClientError: An error occurred (AccessDenied) when calling the PutObject operation: Access Denied\n\nDuring handling of the above exception, another exception occurred:\n\nTraceback (most recent call last):\n  File \"/app/app/api/v1/files.py\", line 33, in upload_file\n    s3_key = await s3_service.upload_file(file, current_user.id)\n             ^^^^^^^^^^^^^^^^^^^^^^^^^^^^^^^^^^^^^^^^^^^^^^^^^^^\n  File \"/app/app/services/s3.py\", line 67, in upload_file\n    raise HTTPException(\nfastapi.exceptions.HTTPException: 500: AWS S3 error: Access Denied\n",
  "user_id": "340003bc-3dbc-4c0b-8c4c-777126934e5d",
  "filename": "chat_export (11).pdf"
}
2024-12-01 20:56:12,709 - app.api.v1.files - INFO - files.py:29 - File upload initiated by user 340003bc-3dbc-4c0b-8c4c-777126934e5d: chat_export (11).pdf
2024-12-01 20:56:12,711 - app.services.s3 - INFO - s3.py:36 - Starting file upload. User: 340003bc-3dbc-4c0b-8c4c-777126934e5d, File: chat_export (11).pdf
2024-12-01 20:56:12,712 - app.services.s3 - DEBUG - s3.py:43 - Generated S3 key: users/340003bc-3dbc-4c0b-8c4c-777126934e5d/f5a26867-515d-4140-bf85-7c67bce857b5.pdf
2024-12-01 20:56:12,712 - app.services.s3 - DEBUG - s3.py:44 - File details - Size: 236395, Type: application/pdf
2024-12-01 20:56:13,560 - app.services.s3 - INFO - s3.py:57 - File upload successful. Time taken: 0.85s
2024-12-01 20:56:13,560 - app.api.v1.files - DEBUG - files.py:34 - File uploaded to S3. Key: users/340003bc-3dbc-4c0b-8c4c-777126934e5d/f5a26867-515d-4140-bf85-7c67bce857b5.pdf
2024-12-01 20:56:13,666 - app.api.v1.files - DEBUG - files.py:48 - Database record created for file: f7ecee5f-c227-4102-b5ea-ae44469a5ed2
2024-12-01 20:56:13,666 - app.services.s3 - DEBUG - s3.py:87 - Generating presigned URL for key: users/340003bc-3dbc-4c0b-8c4c-777126934e5d/f5a26867-515d-4140-bf85-7c67bce857b5.pdf
2024-12-01 20:56:13,675 - app.services.s3 - DEBUG - s3.py:98 - Generated presigned URL with expiry: 3600s
2024-12-01 20:56:13,675 - app.api.v1.files - INFO - files.py:65 - File upload completed successfully. Time taken: 0.97s
